Workbook

Sheet Actors Reference
A1: DRAMOIR · Actors Reference
A2: Actor Name | B2: Photo URL | C2: Dramas
A3: Ahn Bo-Hyun | B3: https://pin.it/3Md90mGxp | C3: {=TEXTJOIN(", ", TRUE, IF(ISNUMBER(SEARCH(A3, 'Kdrama Database '!$G$3:$G$1010)), 'Kdrama Database '!$A$3:$A$1010, ""))} -> Dokgo rewind , Flex x cop, Flex x cop 2, Her private life, Itaewon class, Kairos, Military prosecutor doberman, My name, See you in my 19th life, Spring fever, Wednesday 3:30 PM, Yumi's cells, Yumi's cells 2
A4: Ahn Eun-Jin | B4: https://pin.it/6kFqIqieH | C4: {=TEXTJOIN(", ", TRUE, IF(ISNUMBER(SEARCH(A4, 'Kdrama Database '!$G$3:$G$1010)), 'Kdrama Database '!$A$3:$A$1010, ""))} -> Dynamite kiss, Genie, make a wish, Good casting, Goodbye earth , Hospital playlist 2, My dearest, Strangers from hell, The good bad mom, The one and only
A5: Ahn Hee-Yeon | B5: https://pin.it/5urRceX6H | C5: {=TEXTJOIN(", ", TRUE, IF(ISNUMBER(SEARCH(A5, 'Kdrama Database '!$G$3:$G$1010)), 'Kdrama Database '!$A$3:$A$1010, ""))} -> Call it love, Idol: the coup, Love Alarm 2, Not yet thirty, XX
A6: Ahn Hyo-Seop | B6: https://pin.it/6VISaL2Yu | C6: {=TEXTJOIN(", ", TRUE, IF(ISNUMBER(SEARCH(A6, 'Kdrama Database '!$G$3:$G$1010)), 'Kdrama Database '!$A$3:$A$1010, ""))} -> A business proposal, A time called you, Abyss, Dr. Romantic 2, Dr. Romantic 3, Haechi, Lovers of the red sky, Queen of the ring, Sold out on you, Splash Splash love, Still 17
A7: Ahn Jae Hyun | B7: https://pin.it/7ttZ6ExVs | C7: {=TEXTJOIN(", ", TRUE, IF(ISNUMBER(SEARCH(A7, 'Kdrama Database '!$G$3:$G$1010)), 'Kdrama Database '!$A$3:$A$1010, ""))} -> Cinderella and the four knights, The beauty inside
A8: Ahn Jae-Hong | B8: https://pin.it/59Qh70irf | C8: {=TEXTJOIN(", ", TRUE, IF(ISNUMBER(SEARCH(A8, 'Kdrama Database '!$G$3:$G$1010)), 'Kdrama Database '!$A$3:$A$1010, ""))} -> Be melodramatic, Bloodhounds 2, Fight for my way, Mask girl, Reply 1988
A9: Ahn Ji-Ho | B9: https://pin.it/3RsNBTGW3 | C9: {=TEXTJOIN(", ", TRUE, IF(ISNUMBER(SEARCH(A9, 'Kdrama Database '!$G$3:$G$1010)), 'Kdrama Database '!$A$3:$A$1010, ""))} -> Begins ≠ Youth, Night has come, Nobody knows, The defects
A10: Ahn Seung-Gyun | B10: https://share.google/OHfLq0dBoSua2tNSB | C10: {=TEXTJOIN(", ", TRUE, IF(ISNUMBER(SEARCH(A10, 'Kdrama Database '!$G$3:$G$1010)), 'Kdrama Database '!$A$3:$A$1010, ""))} -> 365: repeat the year, Still 17
A11: Ahn Si-Eun | B11: https://share.google/wzrJr0vyyPofgRUXM | C11: {=TEXTJOIN(", ", TRUE, IF(ISNUMBER(SEARCH(A11, 'Kdrama Database '!$G$3:$G$1010)), 'Kdrama Database '!$A$3:$A$1010, ""))} -> Dr. Romantic 2, Flower ever after, You are my spring
A12: Ahn So-Hee | B12: https://pin.it/2whf6WGmH | C12: {=TEXTJOIN(", ", TRUE, IF(ISNUMBER(SEARCH(A12, 'Kdrama Database '!$G$3:$G$1010)), 'Kdrama Database '!$A$3:$A$1010, ""))} -> Missing: the other side, Missing: the other side 2, Welcome to waikiki 2
A13: Arin | B13: https://pin.it/7BuAOFW4E | C13: {=TEXTJOIN(", ", TRUE, IF(ISNUMBER(SEARCH(A13, 'Kdrama Database '!$G$3:$G$1010)), 'Kdrama Database '!$A$3:$A$1010, ""))} -> My girlfriend is the man, S line
A14: Asahi | B14: https://pin.it/2M4y8UERC | C14: {=TEXTJOIN(", ", TRUE, IF(ISNUMBER(SEARCH(A14, 'Kdrama Database '!$G$3:$G$1010)), 'Kdrama Database '!$A$3:$A$1010, ""))} -> The mysterious class
... A120: Esom | B120: https://pin.it/7GEL1xnr0 | C120: {=TEXTJOIN(", ", TRUE, IF(ISNUMBER(SEARCH(A120, 'Kdrama Database '!$G$3:$G$1010)), 'Kdrama Database '!$A$3:$A$1010, ""))} -> Because this is my first life, Black knight , Phantom lawyer, Save me 2, Taxi driver
A121: Geum Hae-Na | C121: {=TEXTJOIN(", ", TRUE, IF(ISNUMBER(SEARCH(A121, 'Kdrama Database '!$G$3:$G$1010)), 'Kdrama Database '!$A$3:$A$1010, ""))} -> A shop for killers
A122: Geum Sae-Rok | C122: {=TEXTJOIN(", ", TRUE, IF(ISNUMBER(SEARCH(A122, 'Kdrama Database '!$G$3:$G$1010)), 'Kdrama Database '!$A$3:$A$1010, ""))} -> Class of lies
A123: Gil Hae-Yeon | C123: {=TEXTJOIN(", ", TRUE, IF(ISNUMBER(SEARCH(A123, 'Kdrama Database '!$G$3:$G$1010)), 'Kdrama Database '!$A$3:$A$1010, ""))} -> Beyond evil , Doctor on the edge, Law school, The silent sea , The winning try
A124: Go Ah-Sung | C124: {=TEXTJOIN(", ", TRUE, IF(ISNUMBER(SEARCH(A124, 'Kdrama Database '!$G$3:$G$1010)), 'Kdrama Database '!$A$3:$A$1010, ""))} -> Life on mars
A125: Go Ara | C125: {=TEXTJOIN(", ", TRUE, IF(ISNUMBER(SEARCH(A125, 'Kdrama Database '!$G$3:$G$1010)), 'Kdrama Database '!$A$3:$A$1010, ""))} -> Black , Do do sol sol la la sol, Haechi, Hwarang: the beginning, The Scandal of Chunhwa
A126: Go Bo-Gyeol | C126: {=TEXTJOIN(", ", TRUE, IF(ISNUMBER(SEARCH(A126, 'Kdrama Database '!$G$3:$G$1010)), 'Kdrama Database '!$A$3:$A$1010, ""))} -> Black out, Go back couple, Hi bye, mama!, Queen for seven days , The heavenly idol
A127: Go Joon-Hee | C127: {=TEXTJOIN(", ", TRUE, IF(ISNUMBER(SEARCH(A127, 'Kdrama Database '!$G$3:$G$1010)), 'Kdrama Database '!$A$3:$A$1010, ""))} -> She was pretty
A128: Go Kyung-Pyo | C128: {=TEXTJOIN(", ", TRUE, IF(ISNUMBER(SEARCH(A128, 'Kdrama Database '!$G$3:$G$1010)), 'Kdrama Database '!$A$3:$A$1010, ""))} -> Chicago typewriter , Connect , Cross, D.P 2, Frankly speaking, Private lives, Reply 1988, Strongest deliveryman, Undercover miss hong
A129: Go Min-Si | C129: {=TEXTJOIN(", ", TRUE, IF(ISNUMBER(SEARCH(A129, 'Kdrama Database '!$G$3:$G$1010)), 'Kdrama Database '!$A$3:$A$1010, ""))} -> Jirisan, Love Alarm 1, Love Alarm 2, Sweet home 1, Sweet home 2, Sweet home 3, Tastefully yours, The frog, The smile has left your eyes, Youth of may
A130: Go Soo | C130: {=TEXTJOIN(", ", TRUE, IF(ISNUMBER(SEARCH(A130, 'Kdrama Database '!$G$3:$G$1010)), 'Kdrama Database '!$A$3:$A$1010, ""))} -> Missing: the other side, Missing: the other side 2, Money game, Witch's love
A131: Go Soo-Hee | C131: {=TEXTJOIN(", ", TRUE, IF(ISNUMBER(SEARCH(A131, 'Kdrama Database '!$G$3:$G$1010)), 'Kdrama Database '!$A$3:$A$1010, ""))} -> Witch's love
A132: Go Won-Hee | C132: {=TEXTJOIN(", ", TRUE, IF(ISNUMBER(SEARCH(A132, 'Kdrama Database '!$G$3:$G$1010)), 'Kdrama Database '!$A$3:$A$1010, ""))} -> King the land, Love to hate you, Strongest deliveryman, Welcome to waikiki 1
... A134: Go Youn-Jung | C134: {=TEXTJOIN(", ", TRUE, IF(ISNUMBER(SEARCH(A134, 'Kdrama Database '!$G$3:$G$1010)), 'Kdrama Database '!$A$3:$A$1010, ""))} -> Alchemy of souls 2, Can this love be translated?, Death's game, He is psychometric, Law school, Moving , Moving 2, Resident playbook, Sweet home 1, We are all trying here
A135: Gong Hyo-Jin | B135: https://pin.it/133xRgun5 | C135: {=TEXTJOIN(", ", TRUE, IF(ISNUMBER(SEARCH(A135, 'Kdrama Database '!$G$3:$G$1010)), 'Kdrama Database '!$A$3:$A$1010, ""))} -> A bona fide killer , When the camellia blooms, When the stars gossip
A136: Gong Min-Jung | B136: https://pin.it/3frsHZcI0 | C136: {=TEXTJOIN(", ", TRUE, IF(ISNUMBER(SEARCH(A136, 'Kdrama Database '!$G$3:$G$1010)), 'Kdrama Database '!$A$3:$A$1010, ""))} -> Boyfriend on demand, Hometown cha cha cha, Love: track, Marry my husband, Please don't date him, Sorry not Sorry
A137: Gong Myung | B137: https://pin.it/3dUftlzdX | C137: {=TEXTJOIN(", ", TRUE, IF(ISNUMBER(SEARCH(A137, 'Kdrama Database '!$G$3:$G$1010)), 'Kdrama Database '!$A$3:$A$1010, ""))} -> Be melodramatic, Filing for love, Lovers of the red sky, Mercy for none, Second shot at love, The bride of habaek, Way back love
A138: Gong Seung-Yeon | B138: https://pin.it/1RXfPzUJ1 | C138: {=TEXTJOIN(", ", TRUE, IF(ISNUMBER(SEARCH(A138, 'Kdrama Database '!$G$3:$G$1010)), 'Kdrama Database '!$A$3:$A$1010, ""))} -> Are you human too?, Bulgasal: immortal souls , Karma, My lovely journey, My lovely journey 2, My shy boss, Perfect crown, Six flying dragon , The first responders 1, The first responders 2
A139: Kong Seong-Ha | B139: https://share.google/5uSFFP4jeQgLMXMrl | C139: {=TEXTJOIN(", ", TRUE, IF(ISNUMBER(SEARCH(A139, 'Kdrama Database '!$G$3:$G$1010)), 'Kdrama Database '!$A$3:$A$1010, ""))} -> Doctor slump, Siren's kiss, Through the darkness
A140: Gong Yoo | B140: https://pin.it/qBYfk1eP9 | C140: {=TEXTJOIN(", ", TRUE, IF(ISNUMBER(SEARCH(A140, 'Kdrama Database '!$G$3:$G$1010)), 'Kdrama Database '!$A$3:$A$1010, ""))} -> Goblin, The silent sea , The trunk
A141: Goo Doo-Shim | B141: https://share.google/1jhCnnVHwLUrraqB3 | C141: {=TEXTJOIN(", ", TRUE, IF(ISNUMBER(SEARCH(A141, 'Kdrama Database '!$G$3:$G$1010)), 'Kdrama Database '!$A$3:$A$1010, ""))} -> Our blues, The atypical family
A142: Ha Ji-Won | C142: {=TEXTJOIN(", ", TRUE, IF(ISNUMBER(SEARCH(A142, 'Kdrama Database '!$G$3:$G$1010)), 'Kdrama Database '!$A$3:$A$1010, ""))} -> Chocolate, Climax, Empress ki
A143: Ha Jun | C143: {=TEXTJOIN(", ", TRUE, IF(ISNUMBER(SEARCH(A143, 'Kdrama Database '!$G$3:$G$1010)), 'Kdrama Database '!$A$3:$A$1010, ""))} -> Bad prosecutor , Crazy love, Destined with you, Missing: the other side, Missing: the other side 2, Narco saints , Our universe, Radio romance
A144: Ha Jung-Woo | C144: {=TEXTJOIN(", ", TRUE, IF(ISNUMBER(SEARCH(A144, 'Kdrama Database '!$G$3:$G$1010)), 'Kdrama Database '!$A$3:$A$1010, ""))} -> Narco saints
A145: Ha Seok-Jin | C145: {=TEXTJOIN(", ", TRUE, IF(ISNUMBER(SEARCH(A145, 'Kdrama Database '!$G$3:$G$1010)), 'Kdrama Database '!$A$3:$A$1010, ""))} -> Blind , D-day, To my beloved thief
A146: Ha Yoon-Kyung | C146: {=TEXTJOIN(", ", TRUE, IF(ISNUMBER(SEARCH(A146, 'Kdrama Database '!$G$3:$G$1010)), 'Kdrama Database '!$A$3:$A$1010, ""))} -> Extraordinary attorney woo, Gangnam B-side, See you in my 19th life, The apartment job, Undercover miss hong
...

Sheet Kdrama Database 
A1: DRAMOIR · Drama Database
A2: Title | B2: type | C2: country | D2: Year | E2: Episodes | F2: Status | G2: Main role | H2: Genres | I2: Tropes | J2: Mood / Vibe Tags | K2: Global Rating (/10) | L2: Poster URL | M2: Banner URL | N2: Synopsis | O2: Curated Collections
A3: 100 days my prince | B3: series | C3: Korea | D3: 2018 | E3: 16 | F3: Completed | G3: Do Kyung-Soo, Nam Ji-Hyun, Kim Seon-Ho, Jo Sung-Ha, Han So-Hee, Kim Jae-Yeong | H3: romcom, Drama, historical | I3: Joseon era, contract relationship, fake marriage, Memory Loss / amnesia, Palace intrigue, secret identity, childhood connection / first meeting, fated / destined love, grumpy x sunshine, cold / tsundere ML, found family, secret past revealed, Co-habitation / living together, chemistry overload, hate to tolerance to love | J3: feel-good, comfort drama, chaotic fun, episode 1 hook, aesthetically beautiful, emotional rollercoaster, OST is everything | K3: 7.8 | L3: https://pin.it/1JccWz0Zo | M3: https://pin.it/544vsLYL8 | N3: Lee Yul is an uncompromising, perfectionist Crown Prince who survives an assassination attempt but loses his memory, waking up as a clueless commoner named Won-deuk. Meanwhile, Hong-shim is an intelligent, fiercely independent woman forced into a royal decree to marry immediately or face punishment. The two end up in a chaotic contract marriage, with the spoiled prince struggling to adapt to peasant life while his hidden past catches up to him.
A4: 18 again | B4: series | C4: Korea | D4: 2020 | E4: 16 | F4: Completed | G4: Lee Do-Hyun, Kim Ha-Neul, Yoon Sang-Hyun, Roh Jeong-Eui, Ryeoun, Wi Ha-Joon | H4: romcom, Drama, fantasy, family, school | I4: second chance romance, healing romance, single parent, grumpy x sunshine, protective ML, green flag ML, career-driven FL, hidden true self, family dynamics, adult returning to highschool, highschool setting, character growth, love triangle | J4: healing & therapeutic, cry fest, emotional rollercoaster | K4: 8.6 | L4: https://pin.it/5ClG7w5uB | M4: https://pin.it/4MFsVvX5c | N4: On the brink of divorce and suffering through a dead-end career, 37-year-old Hong Dae-young suddenly morphs back into his peak 18-year-old body while retaining his adult mind. Under a fake identity, he attends his teenage twins' high school, getting a front-row seat to the struggles of the family he unintentionally neglected.
A5: 365: repeat the year | B5: series | C5: Korea | D5: 2020 | E5: 24 | F5: Completed | G5: Lee Jun-Hyuk, Nam Ji-Hyun, Kim Jee-Soo, Lee Sung-Wook, Ahn Seung-Gyun, Yang Dong-Geun, Ryeoun | H5: thriller, mystery, crime, psychological, sci-fi | I5: time travel, parallel world crossing, murder mystery, serial killer hunt, investigation, cat-and-mouse chase, betrayal, secret past revealed, no romance | J5: episode 1 hook, plot twist heavy, dark & heavy | K5: 7.8 | L5: https://pin.it/CWtoIKDlN | M5: https://pin.it/6ACjj7dqP | N5: Ji Hyung-ju is a dedicated homicide detective struggling with the tragic murder of his partner, and Shin Ga-hyun is a successful webtoon artist paralyzed by a sudden hit-and-run accident. They are invited by a mysterious psychiatrist to participate in a "reset," traveling back exactly one year in time to rewrite their fates. However, when the participants begin dying one by one in a series of highly suspicious, calculated murders, they must team up to stop the killer.
A6: 7 first kisses | B6: series | C6: Korea | D6: 2016 | E6: 8 | F6: Completed | G6: Lee Cho-Hee, Choi Ji-Woo, Lee Joon-Gi, Park Hae-Jin, Ji Chang-Wook, Kai, Ok Taec-Yeon, Lee Jong-Suk, Lee Min-Ho | H6: fantasy, comedy, romance | I6: supernatural abilities / powers, magical element, curse / spell, CEO x Employee, Celebrity x Normal Citizen, secret identity, hidden true self, workplace romance, forced proximity, fake dating, clumsy FL, multiple leads, chemistry overload | J6: chaotic fun, easy watch, feel-good | K6: 6.1 | L6: https://pin.it/66cSrnzw9 | M6: https://pin.it/4MCQ0AzeD | N6: Min Soo-jin is a lonely, twenty-five-year-old Duty-Free shop employee who has never had a romantic relationship or experienced a single kiss in her entire life. Her mundane routine turns completely surreal when she helps a mysterious, supernatural goddess who rewards her by granting an extraordinary magical gift: Soo-jin is given the chance to choose between seven distinct, hyper-glorious dream partners across different fantasy scenarios, including a billionaire CEO, a secret agent, and a K-pop superstar.
A7: A beautiful mind | B7: series | C7: Korea | D7: 2016 | E7: 14 | F7: Completed | G7: Jang Hyuk, Park So-Dam, Yoon Hyun-Min, Park Se-Young, Heo Joon-Ho, Oh Jung-Se | H7: medical, mystery, psychological, romance, melodrama | I7: slow burn romance, workplace setting, medical / hospital setting, investigation, murder mystery, cold / tsundere ML, career-driven FL, psychopathic villain, character growth, corruption / power abuse, older ML (oppa), age gap romance, character driven | J7: "slow starter, worth it", underrated gem, dark & heavy | K7: 7.7 | L7: https://pin.it/1RogV7Gkw | M7: https://pin.it/19zQwEfXv | N7: A genius neurosurgeon who is completely unable to feel empathy due to a frontal lobe injury finds himself at the center of a series of mysterious hospital patient deaths. When a stubborn rookie traffic cop begins investigating, she forces him to navigate human emotions for the first time to track down the killer.
A8: A bona fide killer | B8: series | C8: Korea | D8: 2026 | E8: 14 | F8: Completed | G8: Gong Hyo-Jin, Jung joon-Won, Lee Sang-Yi, Shin Hyun-Soo, Sung Dong-Il, Seo Jung-Yeon, Moo Jin-Sung, Ha Yul-Ri, Choi Woo-Sung, Lee Eun-Saem | H8: action, thriller, Drama, crime, comedy | I8: investigation, dark justice, secret identity, hidden true self, smothering mother-in-law, tragic backstory, coming-of-age journey, He-Falls-First, unrequited love, mature romance, Golden Retriever ML, alpha / strong FL, double life, Heroic Save, family dynamics, workplace team bond, murder mystery, secret past revealed | J8: fast-paced, dark & heavy, Intense action, emotional rollercoaster | K8: 7.3 | L8: https://pin.it/1IhU1L6tv | M8: https://pin.it/4aV7deqaL | N8: Yoo Bo-na appears to be an ordinary working mother raising her young daughter with her reporter husband, but she secretly leads a double life as Kingfisher, a legendary assassin who eliminates criminals who escape the law. After returning from maternity leave, she must balance deadly assignments with family life—especially when her husband is tasked with investigating the very assassin whose identity she has sworn to protect.
A9: A business proposal | B9: series | C9: Korea | D9: 2022 | E9: 12 | F9: Completed | G9: Ahn Hyo-Seop, Kim Se-Jeong, Kim Min-Gue, Seol In-Ah | H9: romcom, family | I9: He-Falls-First, fake dating, contract relationship, secret dating, workplace romance, Rich x Poor, CEO x Employee, protective ML, yearning / lovesick ML, career-driven FL, bromance, sisterhood, workplace team bond, mistaken identity, workplace setting, webtoon adaptation, top tier kiss, Calm x Chaotic, chemistry overload | J9: feel-good, easy watch, episode 1 hook, chaotic fun, OST is everything, rewatchable | K9: 8.1 | L9: https://pin.it/OODVjjFRw | M9: https://pin.it/5HrKBENcS | N9: When Shin Ha-ri agrees to disguise herself as a glamorous femme fatale to ruin a blind date on behalf of her wealthy best friend, she expects a quick and chaotic exit. Instead, she finds herself sitting across from Kang Tae-moo—the brilliant, workaholic, and completely ruthless new CEO of her own company, who decides to marry her just to stop his grandfather's nagging.
A10: A good day to be a dog | B10: series | C10: Korea | D10: 2023 | E10: 14 | F10: Completed | G10: Cha Eun-Woo, Park Gyu-Young, Lee Hyun-Woo, Yoon Hyun-Soo | H10: romcom, fantasy, school, Drama | I10: He-Falls-First, forced proximity, healing romance, introvert x extrovert , protective ML, green flag ML, curse / spell, past-life connection, Teacher x Student, workplace setting, highschool setting, supernatural abilities / powers, webtoon adaptation, top tier kiss | J10: feel-good, comfort drama, healing & therapeutic, chaotic fun | K10: 8.2 | L10: https://pin.it/2jvwZuHWv | M10: https://pin.it/37bG9EqEN | N10: High school teacher Han Hae-na harbors a bizarre generational family curse: if she kisses a man, she transforms into a dog at midnight for six hours until she can kiss the same man again in her dog form. After mistakenly kissing her distant colleague, Jin Seo-won, she discovers that breaking her curse will be nearly impossible because he has a debilitating, secret phobia of dogs.
A11: A hundred memories | B11: series | C11: Korea | D11: 2025 | E11: 12 | F11: Completed | G11: Kim Da-Mi, Shin Ye-Eun, Heo Nam-Jun, Kim Jung-Hyun, Lee Won-Jung, Jeon Sung-Woo | H11: romance, Drama, historical, slice-of-life, youth | I11: first love, unresolved feelings , tragic separation, Bittersweet / Realistic romance, sisterhood, coming-of-age journey, grief & loss, adult life struggles, THE confrontation, 1980s setting, retro / period setting, family dynamics, secret past revealed, tragic backstory | J11: emotional rollercoaster, aesthetically beautiful, underrated gem, disappointing ending | K11: 7.6 | L11: https://pin.it/5wAf0PvFB | M11: https://pin.it/4YdVqNEOH | N11: Set in 1980s South Korea, Go Young-rye works as a bus hostess on route 100 while dreaming of going to university. Her life changes when charismatic newcomer Seo Jong-hee joins the bus company, and the two women become close friends. Their friendship becomes complicated when both become connected to Han Jae-pil, leading to first love, rivalry, painful separation, and the struggles of growing into adulthood.
A12: A killer paradox | B12: series | C12: Korea | D12: 2024 | E12: 8 | F12: Completed | G12: Choi Woo-Shik, Son Suk-Ku, Lee Hee-Joon, Hyun Bong-Sik | H12: crime, thriller, mystery, psychological | I12: serial killer hunt, accidental murder / witness, framed for a crime, investigation, mind games / psychological warfare, partners in crime, life lessons, secret identity, dark justice, no romance, dark comedy | J12: binge-worthy, episode 1 hook, plot twist heavy, dark & heavy | K12: 7.1 | L12: https://pin.it/4ISd2MzKJ | M12: https://pin.it/7sOGkXJrR | N12: An ordinary, aimless college student accidentally murders a rude customer during his convenience store part-time job, sending him into a panic. However, he soon discovers that his victim was actually a horrific serial killer—and that he possesses a supernatural, latent ability to instinctively identify evil targets, kicking off a brutal cat-and-mouse game with a relentless police detective.
A13: A korean Odyssey | B13: series | C13: Korea | D13: 2017 | E13: 20 | F13: Completed | G13: Lee Seung-Gi, Cha Seung-Won, Oh Yeon-Seo, Lee Hong-Gi, Jang Gwang, Lee El | H13: romance, fantasy, comedy, horror | I13: Human x Supernatural Entity, supernatural abilities / powers, ghost / spirit, contract relationship, forced proximity, fated / destined love, epic romance, Star-Crossed Lovers, tragic separation, yearning / lovesick ML, second couple syndrome, chemistry overload, hate to tolerance to love | J13: chaotic fun, emotional rollercoaster, plot twist heavy, OST is everything, disappointing ending | K13: 7.9 | L13: https://pin.it/4hi9WoLs4 | M13: https://pin.it/6WvfwPnEs | N13: Son Oh-gong is an extraordinarily powerful, arrogant, and mischievous mythical monkey god who was banished to the human world with his powers sealed. He crosses paths with Jin Seon-mi, a successful real estate CEO who possesses the supernatural ability to see ghosts and demons. Bound by a magical bracelet called the Geumganggo, Oh-gong is forced to become her ultimate, fiercely protective guardian against dark spiritual forces, igniting a dangerous romance.
A14: A love so beautiful | B14: series | C14: Korea | D14: 2020 | E14: 24 | F14: Completed | G14: Kim Yo-Han, So Joo-Yeon, Yeo Hoi-Hyun, Jo Hye-Joo, Jung Jae-Oh | H14: romcom, youth, school, slice-of-life | I14: friends to lovers, school romance, She-Falls-First, first love, second lead syndrome, introvert x extrovert , Calm x Chaotic, cold / tsundere ML, clumsy FL, naive / innocent FL, friends group, neighbours, coming-of-age journey, character growth, highschool setting | J14: comfort drama, feel-good, easy watch | K14: 7.2 | L14: https://pin.it/2ufu9xujc | M14: https://pin.it/4XHf7LevD | N14: A bright, overly cheerful high schooler harboring a massive, seventeen-year unrequited crush on her brilliant, emotionally cold next-door neighbor relentlessly confesses her feelings. The story tracks their close-knit friend group as they transition from clumsy teenagers into young adults facing real-world heartbreaks.
... A30: All of us are dead | B30: series | C30: Korea | D30: 2022 | E30: 12 | F30: Completed | G30: Park Ji-Hu, Yoon Chan-Young, Cho Yi-Hyun, Lomon, Yoo In-Soo, Lee Yoo-Mi, Lee Sang-Hee, Kim Byung-chul | H30: action, thriller, horror, sci-fi, school | I30: zombie / apocalypse, k-trauma, highschool setting, friends group, survival thriller, Heroic Save, grief & loss, betrayal, alpha / strong FL, protective ML, multiple leads, introvert x extrovert, chemistry overload | J30: binge-worthy, episode 1 hook, emotional rollercoaster, dark & heavy, plot twist heavy, gory & violent | K30: 7.6 | L30: https://pin.it/J1Pn0voSQ | M30: https://pin.it/4aRWXjfUE | N30: A regular high school becomes ground zero for a devastating zombie virus outbreak. With no food, no cell service, and no rescue coming from the outside world, a tight-knit squad of students must band together using classroom equipment to survive a bloody escape against their turned classmates.
A31: All of us are dead 2 | B31: series | C31: Korea | D31: 2027 | E31: 12 | F31: Upcoming | G31: Park Ji-Hu, Yoon Chan-Young, Cho Yi-Hyun, Lomon, Lee Min-Jae, Kim Si-Eun, Roh Jae-Won, Yoon Ga-I | H31: action, thriller, horror, sci-fi, school | I31: zombie / apocalypse, k-trauma, friends group, survival thriller, grief & loss, overcoming trauma, life lessons, alpha / strong FL, protective ML, multiple leads | J31: binge-worthy, emotional rollercoaster, dark & heavy, plot twist heavy, gory & violent | L31: https://pin.it/6m01pj1Jp | N31: After surviving the catastrophic zombie outbreak at Hyosan High, Nam On Jo is now a university student in Seoul, struggling to move on from the trauma and the friends she lost. But when a new wave of infection suddenly hits Seoul, she finds herself trapped in another deadly fight for survival — this time without the people she once depended on.
A32: All that we loved | B32: series | C32: Korea | D32: 2023 | E32: 8 | F32: Completed | G32: Oh Se-Hun, jang Yeo-Bin, Cho Jun-Young, Lee Seung-Joon, Jeon Yeong-In, Song Jae-Rim, Jung Eugene | H32: youth, romance, Drama | I32: school romance, highschool setting, bromance, childhood connection / first meeting, friends to lovers, first love, love triangle, second lead syndrome, friends group, hidden true self, coming-of-age journey, supernatural abilities / powers | J32: emotional rollercoaster, aesthetically beautiful, easy watch, cry fest, underrated gem | K32: 7.1 | L32: https://pin.it/4SBhBJfwT | M32: https://pin.it/2v25LAd3v | N32: High school best friends Go Yoo and Go Joon-hee are inseparable, but Joon-hee suffers from severe health issues that require a kidney transplant, which Go Yoo willingly donates. Following the surgery, Joon-hee experiences cellular memory syndrome—inheriting Go Yoo's habits and intense romantic feelings for Han So-yeon, a transfer student who harbors a secret.
A33: Angel's last mission: Love | B33: series | C33: Korea | D33: 2019 | E33: 16 | F33: Completed | G33: Shin Hye-Sun, Kim Myung-Soo, Lee Dong-Gun, Kim Bo-Mi, Do Ji-Won, Kim In-Kwok | H33: romcom, fantasy, Drama | I33: contract relationship, Co-habitation / living together, forced proximity, fated / destined love, forbidden love, tragic separation, grumpy x sunshine, Golden Retriever ML, alpha / strong FL, overcoming trauma, bodyguard duty, childhood connection / first meeting, Human x Supernatural Entity, supernatural abilities / powers, chemistry overload | J33: emotional rollercoaster, feel-good, underrated gem, OST is everything | K33: 7.7 | L33: https://pin.it/2atSSXwES | M33: https://pin.it/4qUikuhqG | N33: Dan is a carefree, mischievous angel who is about to be sent to the afterlife when he is given a crucial, final mission: he must find true love for Lee Yeon-seo, a cynical, cold-hearted ballerina who lost her sight and her dreams in a tragic accident. The mission turns chaotic when the angel falls in love with her himself.
A34: Anna | B34: series | C34: Korea | D34: 2022 | E34: 8 | F34: Completed | G34: Bae Suzy, Jung Eun-Chae, Kim Jun-Han, Park Ye-Young | H34: melodrama, thriller, psychological | I34: secret identity, alpha / strong FL, career-driven FL, psychopathic villain, mind games / psychological warfare, corruption / power abuse, inheritance battle, chaebol family drama, class divide conflict, empowerment, revenge, betrayal, tragic backstory, character driven | J34: plot twist heavy, aesthetically beautiful, binge-worthy | K34: 7.1 | L34: https://pin.it/TzALMzSNi | M34: https://pin.it/3noUJQ16q | N34: Lee Yu-mi is a brilliant but desperately poor woman working exhausting, low-wage jobs. Pushed to her absolute limit by the cruel class divide conflict of an elite family, she decides to steal her wealthy boss's identity, reinventing herself as a highly cultured professor named "Anna"—leading her into a tense, psychological web of lies.
A35: Another miss oh | B35: series | C35: Korea | D35: 2016 | E35: 18 | F35: Completed | G35: Eric Moon, Seo Hyun-Jin, Jeon Hye-Bin, Ye Ji-Won, Kim Ji-Seok | H35: romcom, Drama, fantasy | I35: forced proximity, secret dating, fated / destined love, second lead syndrome, love triangle, healing romance, workplace romance, cold / tsundere ML, clumsy FL, Calm x Chaotic, unnecessary misunderstanding, supernatural abilities / powers, mistaken identity, Co-habitation / living together, hate to tolerance to love | J35: emotional rollercoaster, classic, disappointing ending | K35: 7.7 | L35: https://pin.it/2hDOI6ZrQ | M35: https://pin.it/5aOzF1men | N35: A sound director who was left at the altar develops mysterious, vivid psychic visions of a woman he has never met. When he accidentally ruins the business of a woman named Oh Hae-young—unintentionally mistaking her for his beautiful ex-fiancée who shares the exact same name—their lives become inextricably tangled.
A36: Are you human too? | B36: series | C36: Korea | D36: 2018 | E36: 36 | F36: Completed | G36: Seo Kang-Joon, Gong Seung-Yeon, Kim Sung-ryung, Lee Jun-Hyuk, Park Hwan-Hee | H36: sci-fi, romance, mystery, Drama, action | I36: forced proximity, forbidden love, slow burn romance, protective ML, green flag ML, alpha / strong FL, corruption / power abuse, Heroic Save, bodyguard duty, tech-driven romance, secret identity, Human x Supernatural Entity, chaebol family drama | J36: plot twist heavy, easy watch, underrated gem | K36: 7.9 | L36: https://pin.it/7bPkTmNxF | M36: https://pin.it/72PBQeAIE | N36: When a wealthy chaebol heir falls into a sudden coma following a mysterious accident, his brilliant scientist mother creates a highly advanced, identical AI android named Nam Shin III to take his place. To protect his identity from greedy corporate predators, the completely green flag, empathetic android is assigned a fierce former MMA fighter as his bodyguard.
A37: Arthdal chronicles | B37: series | C37: Korea | D37: 2019 | E37: 18 | F37: Completed | G37: Song Joong-Ki, Jang Dong-Gun, Kim Ji-Won, Kim Ok-Bin, Park Hae-Joon, Park Byung-Eun | H37: historical, romance, fantasy, political, action | I37: fantasy world, Palace intrigue, epic romance, tragic separation, secret identity, Underdog vs. Elite, class divide conflict, alpha / strong FL, protective ML, multiple leads | J37: dark & heavy, emotional rollercoaster, underrated gem | K37: 8.2 | L37: https://pin.it/5gsulms2b | M37: https://pin.it/59AGeBr8L | N37: Set in the mythical, ancient land of Arth during the Bronze Age, Eun-seom is an outcast born with a cursed fate who fights tirelessly to rescue his peaceful Wahan tribe from brutal enslavement. He faces off against Ta-gon, a brilliant, terrifyingly ruthless military war hero who seeks to establish the land's first absolute monarchy through high-stakes political manipulation and tribal bloodshed.
A38: Arthdal chronicles 2 : the sword of aramun | B38: series | C38: Korea | D38: 2023 | E38: 12 | F38: Completed | G38: Lee Joon-Gi, Shin Se-Kyung, Jang Dong-Gun, Kim Ok-Bin, Park Hae-Joon, Park Byung-Eun | H38: historical, romance, fantasy, political, action | I38: fantasy world, Palace intrigue, tragic separation, secret identity, Underdog vs. Elite, class divide conflict, alpha / strong FL, protective ML, multiple leads | J38: dark & heavy, emotional rollercoaster | K38: 8.2 | L38: https://pin.it/51iOldwqq | M38: https://pin.it/5wnXLp2xr | N38: Set eight years after Ta-gon successfully ascended the throne as the inaugural king of Arthdal, the ancient, mythical land faces an monumental war for absolute control. Having spend nearly a decade quelling internal revolts to stand as an unassailable sovereign, Ta-gon must fight to conquer the massive Ago Union, which has successfully united under the fierce leadership of Eun-seom. As the armies clash for survival, the complex fates of legendary heroes, priests, and warriors intertwine to redefine power and prophecy.
A39: As you stood by | B39: series | C39: Korea | D39: 2025 | E39: 12 | F39: Completed | G39: Jeon So-Nee, Lee Yoo-Mi, Jang Seung-Jo, Lee Mu-Saeng, Lee Ho-Jung | H39: Drama, crime, thriller, psychological | I39: investigation, sisterhood, partners in crime, found family, overcoming trauma, grief & loss, mind games / psychological warfare, vigilante justice, betrayal, tragic backstory, Bittersweet / Realistic romance, toxic relationship, k-trauma | J39: plot twist heavy, dark & heavy, emotional rollercoaster, ending will destroy you | K39: 7.5 | L39: https://pin.it/99YinECwl | M39: https://pin.it/4N24zhYv5 | N39: When Hui-su becomes trapped in an abusive marriage, her childhood friend Eun-su, who grew up witnessing domestic violence herself, decides to help her escape. The two women make a desperate plan to murder Hui-su's violent husband, but what initially seems like a foolproof plan quickly goes wrong when an unexpected person from their past threatens to expose everything.
A40: At a distance, spring is green | B40: series | C40: Korea | D40: 2021 | E40: 12 | F40: Completed | G40: Park Ji-Hoon, Kang Min-Ah, Bae In-Hyuk, Kwon Eun-Bin, Woo Da-Vi, Na In-Woo | H40: slice-of-life, romance, Drama, youth, school | I40: friends to lovers, comfort romance, healing romance, grumpy x sunshine, bromance, friends group, coming-of-age journey, overcoming trauma, childhood trauma, school bullying, university / campus, academic pressure | J40: healing & therapeutic, comfort drama, underrated gem | K40: 7.8 | L40: https://pin.it/1FENUfVlj | M40: https://pin.it/3dDTSVf49 | N40: From the outside, wealthy university freshman Yeo Jun has a perfect life, but he secretly hides deep childhood trauma and a severe lack of genuine affection. He forms a complicated, highly unexpected bond with a cynical, fiercely independent third-year student who works multiple jobs to survive, navigating the real struggles of youth together.
A41: Avengers social club | B41: series | C41: Korea | D41: 2017 | E41: 12 | F41: Completed | G41: Lee Yo-Won, Ra Mi-Ran, Myung Se-Bin, Lee Jun-Young, Choi Byung-Mo, Jung Suk-Yong | H41: comedy, Drama, family, slice-of-life, school | I41: no romance, sisterhood, found family, neighborhood squad, adult life struggles, investigation, dark justice, corruption / power abuse, Underdog vs. Elite, empowerment, class divide conflict, revenge, Ajummas lead (middle-aged women), highschool setting | J41: comfort drama, feel-good, "slow starter, worth it" | K41: 7.9 | L41: https://pin.it/6KejcIGMM | M41: https://pin.it/1iMTu6nI1 | N41: Three women from vastly different socio-economic backgrounds—a sheltered chaebol heiress, a traditional market fish store owner, and a submissive housewife—discover they are all victims of betrayal and family domestic abuse. Alongside an underdog high school student, they form a secret, hilarious vigilante alliance to carry out non-violent revenge.
A42: Awaken | B42: series | C42: Korea | D42: 2020 | E42: 16 | F42: Completed | G42: Namgoong Min, Kim Seol-Hyun, Lee Chung-Ah, Yoon Sun-Woo, Jang Hyuk-Jin | H42: thriller, mystery, crime, sci-fi, psychological | I42: investigation, cat-and-mouse chase, murder mystery, psychopathic villain, dark justice, corruption / power abuse, supernatural abilities / powers, secret past revealed, tragic backstory, partners in crime, workplace team bond, alpha / strong FL, protective ML, childhood connection / first meeting | J42: plot twist heavy, dark & heavy, "slow starter, worth it", underrated gem | K42: 7.5 | L42: https://pin.it/6mMJQ5clz | M42: https://pin.it/I1xDpN7YV | N42: A chaotic but brilliant police task force leader and a sharp FBI criminal profiler investigate a terrifying string of modern "preview murders" that warn victims of their deaths beforehand. The dark trail leads them straight back to uncovering a horrific, classified government experiment that took place in a mysterious village twenty-eight years ago.
A43: Azure spring | B43: series | C43: Korea | D43: 2026 | E43: 6 | F43: Completed | G43: Kang Sang-Joon, Yeri, Ko Ju-Hee, Jung yeon-Min | H43: slice-of-life, youth, Drama | I43: unresolved feelings , comfort romance, village romance, Co-habitation / living together, forced proximity, introvert x extrovert , grumpy x sunshine, green flag ML, found family, healing journey, secret past revealed, small town / island setting | J43: aesthetically beautiful, comfort drama, easy watch, healing & therapeutic | K43: 6.5 | L43: https://pin.it/5QbE5qQ89 | M43: https://pin.it/2NOCkgzTm | N43: An anxious city job seeker reeling from a failed career path escapes to a quiet island village in Haenam-gun, where she crosses paths with a guarded local man paralyzed by a deep personal trauma. Seeking a clean slate, both decide to learn the rigorous traditional practice of freediving as haenyeo and haenam, letting the rhythm of the ocean slowly heal their buried emotional wounds.
... A76: Boyhood | B76: series | C76: Korea | D76: 2023 | E76: 10 | F76: Completed | G76: Im Si-Wan, Lee Sun-Bin, Lee Si-Woo, Kang Hye-Won | H76: comedy, action, thriller, youth, school | I76: no romance, secret identity, mistaken identity, school bullying, underdog squad, friends group, coming-of-age journey, highschool setting, 1980s setting, retro / period setting, family dynamics, street fights / hand-to-hand combat | J76: chaotic fun, feel-good, binge-worthy, underrated gem | K76: 7.9 | L76: https://pin.it/1keUpwqbk | M76: https://pin.it/7v5h0sOAp | N76: Jang Byeong-gu is a clumsy, weak, and chronically bullied high school student living in rural South Chungcheong Province in 1989. His miserable life takes an unbelievable turn when he transfers to a new agricultural school and is instantly mistaken for the "White Tiger of Asan"—a legendary, undefeated high school street fighter. Embracing his accidental secret identity, Byeong-gu steps into the spotlight as the school's top dog, leading to chaotic high school standoffs.
A77: Boyhood 2 | B77: series | C77: Korea | D77: 2026 | F77: Upcoming | G77: Im Si-Wan, Lee Sun-Bin | H77: comedy, action, thriller, youth, school | I77: highschool setting, school bullying, secret identity, 1980s setting, street fights / hand-to-hand combat, underdog squad, friends group, coming-of-age journey, character growth | J77: chaotic fun, feel-good | L77: https://pin.it/6jtnEr3Rm | N77: Picking up after the chaotic events of the 1989 school year, clumsy student Jang Byeong-gu finds his hard-won peace threatened when real heavy-hitting fighters and a new crop of transfer students arrive in South Chungcheong Province. Forced to defend his accidental legacy and protect his loyal underdog squad, Byeong-gu must navigate escalating high school rivalries, complex retro romance, and the challenges of entering adulthood.
A78: Branding in seongsu | B78: series | C78: Korea | D78: 2024 | E78: 24 | F78: Completed | G78: Kim Ji-Eun, Lomon, Yang Hye-Ji, Kim Ho-Young | H78: romance, fantasy, Drama | I78: enemies to lovers, forced proximity, workplace romance, CEO x Employee, grumpy x sunshine, alpha / strong FL, career-driven FL, soul swap, investigation, mind games / psychological warfare, workplace setting | J78: binge-worthy, plot twist heavy, chaotic fun | K78: 6.5 | L78: https://pin.it/3IXfNcBlj | M78: https://pin.it/W2nDaulyp | N78: A ruthless, workaholic marketing agency team leader and a completely unmotivated, warm-hearted intern find their souls swapped after an accidental, unexpected kiss. Trapped in each other's bodies, they are forced to co-manage high-stakes brand campaigns while searching for a way to reverse the switch.
A79: Brewing love | B79: series | C79: Korea | D79: 2024 | E79: 12 | F79: Completed | G79: Kim Se-Jeong, Lee Jong-Won, Shin Do-Hyun, Baek Sung-Chul | H79: romcom, Drama, slice-of-life | I79: hate to tolerance to love, He-Falls-First, slow burn romance, workplace romance, village romance, introvert x extrovert , grumpy x sunshine, green flag ML, alpha / strong FL, career-driven FL, workplace team bond, small town / island setting, second couple syndrome | J79: comfort drama, feel-good, healing & therapeutic, binge-worthy | K79: 7 | L79: https://pin.it/1VlkVe9hA | M79: https://pin.it/5QC32pTNa | N79: A highly energetic, former special forces member turned top sales representative for a major liquor company goes all out to save her local branch. Her mission requires her to recruit a brilliant, hyper-sensitive master brewer who can sense other people's emotions, triggering a clash of totally opposite personalities.
A80: Bridal mask | B80: series | C80: Korea | D80: 2012 | E80: 28 | F80: Completed | G80: Joo Won, Jin Se-Yeon, Han Chae-Ah, Park Ki-Woong | H80: action, historical, Drama, political, romance | I80: secret identity, undercover, dark justice, vigilante justice, enemies to lovers, second lead syndrome, tragic separation, tragic backstory, betrayal, red flag ML | J80: classic, Intense action, emotional rollercoaster | K80: 8.1 | L80: https://pin.it/5WAadanZ1 | M80: https://pin.it/5fYhY0duH | N80: Lee Kang-to is an ambitious Korean police officer working for the oppressive Japanese regime, reviled by his countrymen as a ruthless traitor. When a masked vigilante known as "Bridal Mask" protecting the innocent turns out to be tied to his own family's tragic past, Kang-to secretly dons the mask himself, living a dangerous double life as both a ruthless officer and a revolutionary hero.
A81: Bring it on, Ghost | B81: series | C81: Korea | D81: 2016 | E81: 16 | F81: Completed | G81: Ok Taec-Yeon, Kim So-Hyun, Kwon Yul, Kim Sang-Ho, Kang Ki-Young | H81: romcom, horror, fantasy, school | I81: Human x Supernatural Entity, supernatural abilities / powers, ghost / spirit, Co-habitation / living together, forced proximity, contract relationship, partners in crime, university / campus, highschool setting, Memory Loss / amnesia, green flag ML, She-Falls-First, hate to tolerance to love | J81: feel-good, chaotic fun, easy watch, emotional rollercoaster | K81: 7.6 | L81: https://pin.it/6cGcK7L7e | M81: https://pin.it/2NBWAxlIe | N81: Park Bong-pal is a lonely university student who uses his supernatural ability to see and punch ghosts to work as a profitable part-time exorcist, saving money to remove his cursed eyes. He encounters Kim Hyun-ji, a feisty, wandering high school ghost who has been suffering from memory loss for five years. Discovering that kissing Bong-pal triggers brief flashbacks of her past life, she convinces him to become her live-in ghostbusting partner, sparking a comedic romance.
A82: Bubblegum | B82: series | C82: Korea | D82: 2015 | E82: 16 | F82: Completed | G82: Lee Dong-Wook, Jung Ryeo-Won, Lee Jong-Hyuk 1, Park Hee-Von, Bae Jong-Ok, Lee Seung-Joon | H82: romcom, Drama, slice-of-life | I82: friends to lovers, first love, secret dating, healing romance, comfort romance, friends group, character growth, overcoming trauma, childhood trauma, adult life struggles, grief & loss, family dynamics, tragic backstory | J82: healing & therapeutic, emotional rollercoaster, aesthetically beautiful | K82: 6.3 | L82: https://pin.it/7xuyMG7aD | M82: https://pin.it/KgIAwmtih | N82: A compassionate eastern medicine doctor and an energetic radio producer have been completely inseparable since early childhood, acting more like protective family than friends. As they enter adulthood, they must confront their hidden, lingering feelings for each other while dealing with complex family opposition and deep emotional scars.
A83: Bulgasal: immortal souls | B83: series | C83: Korea | D83: 2022 | E83: 16 | F83: Completed | G83: Lee Jin-Wook, Kwon Nara, Lee Joon, Gong Seung-yeon, Jung Jin-Young, Kim Woo-Seok, Park Myung-Shin | H83: fantasy, Drama, thriller, mystery | I83: fated / destined love, reincarnation, past-life connection, curse / spell, Human x Supernatural Entity, magical element, epic romance, tragic separation, investigation, serial killer hunt, protective ML, alpha / strong FL, found family | J83: episode 1 hook, plot twist heavy, dark & heavy, aesthetically beautiful | K83: 7.4 | L83: https://pin.it/7wMuwJk65 | M83: https://pin.it/33bx4Xnwk | N83: A cursed man who has lived as an immortal being for over 600 years hunts for the reincarnation of the woman who stole his soul and made him a monster. Across centuries of death and rebirth, their paths cross with an array of characters, leading to an epic, dark fantasy battle for vengeance.
A84: Buried hearts | B84: series | C84: Korea | D84: 2025 | E84: 16 | F84: Completed | G84: Park Hyung-Sik, Heo Joon-Ho, Lee Hae-Young, Hong Hwa-Yeon, Woo Hyun, Kwon Soo-Hyun, Youn Sang-Hyun, Kim Jung-Nam | H84: crime, thriller, mystery, political, romance | I84: betrayal, tragic backstory, grief & loss, corruption / power abuse, mind games / psychological warfare, investigation, murder mystery, yearning / lovesick ML, top tier kiss, chemistry overload | J84: episode 1 hook, dark & heavy, emotional rollercoaster, underrated gem | K84: 7.3 | L84: https://pin.it/1HNM8xjyx | M84: https://pin.it/3GAG5vuL1 | N84: Seo Dong-ju, a talented executive at Daesan Group, secretly hacks into a massive political slush fund worth two trillion won. After being betrayed and targeted in a deadly attack, he survives but loses his memory. As the powerful people behind the missing money desperately try to recover it, Dong-ju becomes caught in a dangerous struggle involving corporate ambition, political power, betrayal, and revenge.
A85: Call it love | B85: series | C85: Korea | D85: 2023 | E85: 16 | F85: Completed | G85: Kim Young-Kwang, Lee Sung-Kyung, Sung Joon, Ahn Hee-Yeon, Kim Ye-Won | H85: melodrama, romance, slice-of-life, Drama | I85: hate to tolerance to love, revenge, hidden true self, workplace romance, slow burn romance, comfort romance, Bittersweet / Realistic romance, calm x calm, Calm x Chaotic, green flag ML, childhood trauma, adult life struggles, workplace setting, top tier kiss, character driven | J85: healing & therapeutic, emotional rollercoaster, "slow starter, worth it", aesthetically beautiful, underrated gem, comfort drama | K85: 7.7 | L85: https://pin.it/7m6vr0gp9 | M85: https://pin.it/5K8otvEze | N85: Sim Woo-joo’s life is completely ruined after she discovers her father's long-term infidelity, and her family is abruptly kicked out of their home by his mistress right after his sudden death. Driven by deep resentment, she plans a meticulous revenge by targeting Han Dong-jin—the mistress’s deeply lonely, workaholic, and emotionally exhausted son. However, as she gets closer to him and witnesses his own hidden misery, her thirst for vengeance blurs into unexpected, heartbreaking empathy.
A86: Can this love be translated? | B86: series | C86: Korea | D86: 2026 | E86: 12 | F86: Completed | G86: Kim Seon-Ho, Go Youn-Jung, Sota Fukushi, Lee E-Dam, Choi Woo-Sung, Kim Won-Hae | H86: romcom, fantasy | I86: She-Falls-First, mutual pining, second lead breaks your heart, second lead syndrome, healing romance, slow burn romance, workplace romance, forced proximity, top tier kiss, Calm x Chaotic, Celebrity x Normal Citizen, overseas / abroad setting, overcoming trauma, hidden true self, THE confrontation, chemistry overload, second couple syndrome, character driven | J86: aesthetically beautiful, OST is everything, feel-good, episode 1 hook | K86: 7.8 | L86: https://pin.it/a80uTzBXK | M86: https://pin.it/bjQqvaL95 | N86: A genius multilingual interpreter who prefers logical barriers over romantic messiness takes a job on an international travel dating show. He ends up translating for a top global actress hiding deep personal anxieties, leading them into a web of emotional misunderstandings as they struggle to find the right words for each other
A87: Captivating the king | B87: series | C87: Korea | D87: 2024 | E87: 16 | F87: Completed | G87: Jo Jung-Suk, Shin Se-Kyung, Lee Shin-Young, Park Ye-Young, Choi Dae-Hoon, Lee Gyu-Hoe, Yang Kyung-Won, Cho Seong-Ha, Son Hyun-Joo | H87: romance, melodrama, historical, political, Drama | I87: Joseon era, Palace intrigue, secret identity, enemies to lovers, revenge, betrayal, cold / tsundere ML, fated / destined love, Star-Crossed Lovers | J87: dark & heavy, plot twist heavy, emotional rollercoaster, aesthetically beautiful | K87: 7.6 | L87: https://pin.it/1I6uYvezr | M87: https://pin.it/4XKGFyOvR | N87: Lee In is a deeply lonely, emotionally exhausted prince caught in severe royal family friction, who finds true solace playing Baduk with an enigmatic, brilliant street player. When he ascends the throne as King, he is forced to become a cold-blooded ruler to survive intense palace intrigue. Years later, his old friend returns under a secret identity as a male Baduk master—but she is actually a fierce female spy seeking absolute political revenge.
...

Sheet Movies Database
A1: DRAMOIR · Drama Database
A2: Title | B2: type | C2: country | D2: year | E2: Genres | F2: Tropes | G2: Mood / Vibe Tags | H2: Global Rating (/10) | I2: Poster URL | J2: Banner URL | K2: Synopsis
A3: #Alive | B3: movie
A4: 18×2 beyond youthful days | B4: movie
A5: 1987: when the day comes | B5: movie
A6: 20th century girl | B6: movie
A7: a little red flower | B7: movie
A8: a man and a woman | B8: movie
A9: a werewolf boy | B9: movie
A10: a year -end medley | B10: movie
A11: after my death | B11: movie
A12: almost love | B12: movie
A13: always | B13: movie
A14: badland hunters | B14: movie
... A22: colony | B22: movie
A23: Concrete market | B23: movie | H23: 5.2
A24: concrete utopia | B24: movie
A25: confession | B25: movie
A26: confidential assignment | B26: movie
A27: confidential assignment 2: international | B27: movie
A28: cry me a sad river | B28: movie
A29: D-day | B29: movie
A30: dark nuns | B30: movie
A31: ditto | B31: movie
A32: door lock | B32: movie
A33: drawing closer | B33: movie
A34: dream | B34: movie
A35: emergency declaration | B35: movie
... A164: A diamond in the rough | B164: movie
B165: movie

Sheet reality shows Database 
A1: DRAMOIR · Drama Database
A2: Title | B2: type | C2: country | D2: Year | E2: Mood / Vibe Tags | F2: Global Rating (/10) | G2: Poster URL | H2: Banner URL | I2: Synopsis

Sheet JDrama Database 
A2: Title | B2: type | C2: country | D2: Year | E2: Episodes | F2: Status | G2: Cast | H2: Genres | I2: Tropes | J2: Mood / Vibe Tags | K2: Global Rating (/10) | L2: Poster URL | M2: Banner URL | N2: Synopsis

Sheet CDrama Database 
A2: Title | B2: type | C2: country | D2: Year | E2: Episodes | F2: Status | G2: Cast | H2: Genres | I2: Tropes | J2: Mood / Vibe Tags | K2: Global Rating (/10) | L2: Poster URL | M2: Banner URL | N2: Synopsis

Sheet 🎞️ Genres
A1: DRAMOIR · Genres — 26 genres
A2: Genre | B2: Notes / Description
A3: romcom
A4: comedy
A5: romance
A6: Drama
A7: melodrama
A8: fantasy
A9: historical
A10: slice-of-life
A11: youth
A12: action
A13: crime
A14: thriller
... A27: family

Sheet 🎭 Tropes
A1: DRAMOIR · Tropes Reference — 274 tropes · 21 categories
A2: Category | B2: Trope
A3: ❤️ How They Fall | B3: hate to tolerance to love
B4: enemies to lovers
B5: friends to lovers
B6: love at first sight
B7: He-Falls-First
B8: She-Falls-First
B9: mutual pining
A10: 💍 Relationship Setups | B10: fake dating
B11: fake marriage
B12: contract relationship
B13: Co-habitation / living together
B14: forced proximity
B15: secret dating
B16: age gap romance
B17: toxic relationship
B18: right person wrong time
A19: 💕 Romance Foundations | B19: epic romance
B20: fated / destined love
B21: forbidden love
B22: unrequited love
B23: first love
B24: Star-Crossed Lovers
B25: second chance romance
B26: unresolved feelings
B27: tragic separation
B28: love triangle
B29: second lead syndrome
B30: second lead breaks your heart
B31: second couple syndrome
A32: 🌸 Romance Styles & Tones | B32: comfort romance
B33: healing romance
B34: mature romance
B35: Bittersweet / Realistic romance
B36: dark romance
B37: slow burn romance
B38: workplace romance
B39: school romance
B40: village romance
...

Sheet ✨ Mood & Vibe Tags
A1: DRAMOIR · Mood & Vibe Tags — 27 tags
A2: Mood / Vibe Tag | B2: Description
A3: comfort drama | B3: Easy, warm, no stress — perfect to rewatch
A4: feel-good | B4: Leaves you happy and warm
A5: healing & therapeutic | B5: Calming, restorative feeling
A6: emotional rollercoaster | B6: Lots of highs and lows
A7: cry fest | B7: Prepare tissues
A8: easy watch | B8: Low effort, fun and light
A9: rewatchable | B9: Worth watching again
A10: binge-worthy | B10: Can't stop watching, fast pacing
A11: episode 1 hook
A12: fast-paced
A13: slow starter, worth it | B13: Needs a few episodes to pick up
A14: masterpiece
A15: underrated gem | B15: Deserves more attention
A16: ending will destroy you | B16: The finale hits hard
A17: disappointing ending
A18: classic | B18: A must-watch in kdrama history
A19: chaotic fun | B19: Crazy plot but in a good way
A20: Intense action
A21: gory & violent
A22: plot twist heavy | B22: Shocking revelations throughout
A23: dark & heavy | B23: Intense, not for light watching
A24: aesthetically beautiful | B24: Stunning cinematography / visuals
A25: OST is everything | B25: Soundtrack is a highlight
